<sdf version='1.6'>
  <model name='honeybee_payload'>

    <static>0</static>

    <link name='base_link'>
      <frame name='base_link_frame'/>
      <pose frame=''>0 0 0 0 0 0</pose>
      <inertial>
        <pose frame=''>0 0 0 0 0 0</pose>
        <mass>0.66</mass>
        <inertia>
          <ixx>9.305e-4</ixx>
          <ixy>0</ixy>
          <ixz>0</ixz>
          <iyy>1.326e-3</iyy>
          <iyz>0</iyz>
          <izz>1.95e-3</izz>
        </inertia>
      </inertial>
      <collision name='base_link_inertia_collision'>
        <pose frame='base_link_frame'>0 0 0 0 -0 0</pose>
        <geometry>
          <box>
            <size>0.3 0.35 0.14</size>
          </box>
        </geometry>
        <surface>
          <contact>
            <ode>
              <min_depth>0.001</min_depth>
              <max_vel>0</max_vel>
            </ode>
          </contact>
          <friction>
            <ode/>
          </friction>
        </surface>
      </collision>
      <visual name='base_link_inertia_visual'>
        <pose frame='base_link_frame'>0 0 -0.06 0 0 1.570796</pose>
        <geometry>
          <box>
            <size>0.2 0.3 0.1</size>
          </box>
          <!-- <mesh>
            <scale>1 1 1</scale>
            <uri>model://honeybee_payload/meshes/honeybee.dae</uri>
          </mesh> -->
        </geometry>
        <material>
          <script>
            <uri>file://media/materials/scripts/gazebo.material</uri>
            <name>Gazebo/BlueTransparent</name>
          </script>
        </material>
      </visual>
      <gravity>1</gravity>
      <velocity_decay/>
    </link>

    <!-- edit here for link length -->
    <!-- link: <pose frame=''> 0 0 -L 0 0 0</pose>
    joint: <pose frame=''> 0 0 L 0 0 0 </pose> -->

    <link name='payload'>
      <frame name='payload_frame'/>
      <pose frame=''>0 0 -0.5 0 0 0</pose>
      <inertial>
        <mass>0.2</mass>
        <pose frame='payload_frame'>0 0 0 0 0 0</pose>
        <inertia>
          <ixx>0.01</ixx>
          <iyy>0.01</iyy>
          <izz>0.01</izz>
          <ixy>0</ixy>
          <ixz>0</ixz>
          <iyz>0</iyz>
        </inertia>
      </inertial>

      <visual name='rod_visual'>
        <pose frame='payload_frame'> 0 0 0.25 0 0 0 </pose>
        <geometry>
            <cylinder>
              <radius>0.004</radius>
              <length>0.5</length>
            </cylinder>
        </geometry>
      </visual>

      <visual name='mass_visual'>
          <pose frame='payload_frame'> 0 0 0 0 0 0 </pose>
          <geometry>
            <cylinder>
              <radius>0.0225</radius>
              <length>0.13</length>
            </cylinder>
          </geometry>
          <transparency>0.7</transparency>
      </visual>
    </link>

    <joint name="pendulum_arm_to_uav" type="universal">
      <parent>base_link</parent>
      <child>payload</child>
      <pose frame=''> 0 0 0.5 0 0 0 </pose>
        <axis>
          <xyz>1 0 0</xyz>
        </axis>
        <axis2>
          <xyz>0 1 0</xyz>
        </axis2>
    </joint>

    <link name='/imu_link'>
      <pose frame=''>0 0 0 0 -0 0</pose>
      <inertial>
        <pose frame=''>0 0 0 0 -0 0</pose>
        <mass>1e-15</mass>
        <inertia>
          <ixx>1e-15</ixx>
          <ixy>0</ixy>
          <ixz>0</ixz>
          <iyy>1e-15</iyy>
          <iyz>0</iyz>
          <izz>1e-15</izz>
        </inertia>
      </inertial>
    </link>
    <joint name='/imu_joint' type='revolute'>
      <child>/imu_link</child>
      <parent>base_link</parent>
      <axis>
        <xyz>1 0 0</xyz>
        <limit>
          <lower>0</lower>
          <upper>0</upper>
          <effort>0</effort>
          <velocity>0</velocity>
        </limit>
        <dynamics>
          <spring_reference>0</spring_reference>
          <spring_stiffness>0</spring_stiffness>
        </dynamics>
        <use_parent_model_frame>1</use_parent_model_frame>
      </axis>
    </joint>

    <model name='gps0'>
      <link name='link'>
        <pose frame=''>0 0 0 0 -0 0</pose>
        <inertial>
          <pose frame=''>0 0 0 0 -0 0</pose>
          <mass>1e-15</mass>
          <inertia>
            <ixx>1e-15</ixx>
            <ixy>0</ixy>
            <ixz>0</ixz>
            <iyy>1e-15</iyy>
            <iyz>0</iyz>
            <izz>1e-15</izz>
          </inertia>
        </inertial>
        <sensor name='gps' type='gps'>
          <pose frame=''>0 0 0 0 -0 0</pose>
          <plugin name='gps_plugin' filename='libgazebo_gps_plugin.so'>
            <robotNamespace/>
            <gpsNoise>0</gpsNoise>
            <gpsXYRandomWalk>2.0</gpsXYRandomWalk>
            <gpsZRandomWalk>4.0</gpsZRandomWalk>
            <gpsXYNoiseDensity>0.0002</gpsXYNoiseDensity>
            <gpsZNoiseDensity>0.0004</gpsZNoiseDensity>
            <gpsVXYNoiseDensity>0.2</gpsVXYNoiseDensity>
            <gpsVZNoiseDensity>0.4</gpsVZNoiseDensity>
          </plugin>
        </sensor>
      </link>
    </model>
    <joint name='gps0_joint' type='fixed'>
      <parent>base_link</parent>
      <child>gps0::link</child>
    </joint>

    <!-- <plugin name='groundtruth_plugin' filename='libgazebo_groundtruth_plugin.so'>
      <robotNamespace/>
    </plugin> -->

    <plugin name='magnetometer_plugin' filename='libgazebo_magnetometer_plugin.so'>
      <robotNamespace/>
      <pubRate>100</pubRate>
      <noiseDensity>0.0004</noiseDensity>
      <randomWalk>6.4e-06</randomWalk>
      <biasCorrelationTime>600</biasCorrelationTime>
      <magTopic>/mag</magTopic>
    </plugin>

    <plugin name='barometer_plugin' filename='libgazebo_barometer_plugin.so'>
      <robotNamespace/>
      <pubRate>50</pubRate>
      <baroTopic>/baro</baroTopic>
      <baroDriftPaPerSec>0</baroDriftPaPerSec>
      <baroNoise>0</baroNoise>
    </plugin>

    <plugin name='mavlink_interface' filename='libgazebo_mavlink_interface.so'>
      <robotNamespace/>
      <imuSubTopic>/imu</imuSubTopic>
      <magSubTopic>/mag</magSubTopic>
      <baroSubTopic>/baro</baroSubTopic>
      <mavlink_addr>INADDR_ANY</mavlink_addr>
      <mavlink_udp_port>14560</mavlink_udp_port>
      <mavlink_tcp_port>4560</mavlink_tcp_port>
      <serialEnabled>0</serialEnabled>
      <serialDevice>/dev/ttyACM0</serialDevice>
      <baudRate>921600</baudRate>
      <qgc_addr>INADDR_ANY</qgc_addr>
      <qgc_udp_port>14550</qgc_udp_port>
      <sdk_addr>INADDR_ANY</sdk_addr>
      <sdk_udp_port>14540</sdk_udp_port>
      <hil_mode>0</hil_mode>
      <hil_state_level>0</hil_state_level>
      <vehicle_is_tailsitter>0</vehicle_is_tailsitter>
      <send_vision_estimation>0</send_vision_estimation>
      <send_odometry>1</send_odometry>
      <enable_lockstep>1</enable_lockstep>
      <use_tcp>1</use_tcp>
      <motorCommandPubTopic>/gazebo/command/motor_throttle</motorCommandPubTopic>
    </plugin>
    <static>0</static>

    <plugin name='rotors_gazebo_imu_plugin' filename='libgazebo_imu_plugin.so'>
      <robotNamespace/>
      <linkName>/imu_link</linkName>
      <imuTopic>/imu</imuTopic>
      <gyroscopeNoiseDensity>0.00018665</gyroscopeNoiseDensity>
      <gyroscopeRandomWalk>3.8785e-05</gyroscopeRandomWalk>
      <gyroscopeBiasCorrelationTime>1000.0</gyroscopeBiasCorrelationTime>
      <gyroscopeTurnOnBiasSigma>0.0087</gyroscopeTurnOnBiasSigma>
      <accelerometerNoiseDensity>0.00186</accelerometerNoiseDensity>
      <accelerometerRandomWalk>0.006</accelerometerRandomWalk>
      <accelerometerBiasCorrelationTime>300.0</accelerometerBiasCorrelationTime>
      <accelerometerTurnOnBiasSigma>0.196</accelerometerTurnOnBiasSigma>
    </plugin>

    <!-- Thrust based motor plugin: -->
    <plugin name='actuators' filename='libgazebo_forces_moments_actuators_plugin.so'>
      <robotNamespace/>
      <linkName>base_link</linkName>
      <copterConfig>4x</copterConfig>
      <motorTimeConstant>0.05</motorTimeConstant>
      <armLength>0.11</armLength>
      <virtualYawMomentArm>0.00799</virtualYawMomentArm>
      <!-- Use maxMotorThrust for a linear motor model or motor_models for a complete 3rd order motor model -->

      <!-- <maxMotorThrust>6.85</maxMotorThrust> -->
      <motor_models>
        <motor name='motor1'>
          <motor_index>0</motor_index>
          <coeffs>-0.0000000035084590 0.0000162700332387 -0.0172207586741500 4.5281385794990241</coeffs>
        </motor>
        <motor name='motor2'>
          <motor_index>1</motor_index>
          <coeffs>-0.0000000035084590 0.0000162700332387 -0.0172207586741500 4.5281385794990241</coeffs>
        </motor>
        <motor name='motor3'>
          <motor_index>2</motor_index>
          <coeffs>-0.0000000035084590 0.0000162700332387 -0.0172207586741500 4.5281385794990241</coeffs>
        </motor>
        <motor name='motor4'>
          <motor_index>3</motor_index>
          <coeffs>-0.0000000035084590 0.0000162700332387 -0.0172207586741500 4.5281385794990241</coeffs>
        </motor>
      </motor_models>
    </plugin>

  </model>
</sdf>
